<?xml version="1.0" encoding="utf-8"?>
<!-- This URDF was automatically created by SolidWorks to URDF Exporter! Originally created by Stephen Brawner (brawner@gmail.com) 
     Commit Version: 1.6.0-4-g7f85cfe  Build Version: 1.6.7995.38578
     For more information, please see http://wiki.ros.org/sw_urdf_exporter -->
<robot
  name="diablo_pluspro_stand">
  <material name="black">
    <color rgba="0.0 0.0 0.0 1.0"/>
  </material>
  <material name="blue">
      <color rgba="0.0 0.0 0.8 1.0"/>
  </material>
  <material name="green">
      <color rgba="0.0 0.8 0.0 1.0"/>
  </material>
  <material name="grey">
      <color rgba="0.2 0.2 0.2 1.0"/>
  </material>
  <material name="silver">
      <color rgba="0.9137254901960784 0.9137254901960784 0.8470588235294118 1.0"/>
  </material>
  <material name="orange">
      <color rgba="1.0 0.4235294117647059 0.0392156862745098 1.0"/>
  </material>
  <material name="brown">
      <color rgba="0.8705882352941177 0.8117647058823529 0.7647058823529411 1.0"/>
  </material>
  <material name="red">
      <color rgba="0.8 0.0 0.0 1.0"/>
  </material>
  <material name="white">
      <color rgba="1.0 1.0 1.0 1.0"/>
  </material>
  <link
    name="base_link">
    <inertial>
      <origin
        xyz="0.017899 -0.019179 0.16091"
        rpy="0 0 0" />
      <mass
        value="11.47" />
      <inertia
        ixx="0.8371974"
        ixy="-0.06254957"
        ixz="-0.01618499"
        iyy="0.8708397"
        iyz="0.003006719"
        izz="0.3425067" />
    </inertial>
    <visual>
      <origin
        xyz="0 0 0"
        rpy="0 0 0" />
      <geometry>
        <mesh
          filename="../meshes/base_link.STL" />
      </geometry>
      <material
        name="">
        <color
          rgba="1 1 1 1" />
      </material>
    </visual>
    <collision>
      <origin
        xyz="0 0 0"
        rpy="0 0 0" />
      <geometry>
        <mesh
          filename="../meshes/base_link.STL" />
      </geometry>
    </collision>
  </link>
  <link name="left_hip_link">
    <inertial>
      <origin
        xyz="-0.028034 0.083955 -0.03225"
        rpy="0 0 0" />
      <mass
        value="5.1" />
      <inertia
        ixx="0.052637715"
        ixy="0.0038396366"
        ixz="0.0029020553"
        iyy="0.018328965"
        iyz="0.0038831563"
        izz="0.051893499" />
    </inertial>
    <visual>
      <origin
        xyz="0 0 0"
        rpy="0 0 0" />
      <geometry>
        <mesh
          filename="../meshes/left_hip_link.STL" />
      </geometry>
      <material
        name="">
        <color
          rgba="1 1 1 1" />
      </material>
    </visual>
    <collision>
      <origin
        xyz="0 0 0"
        rpy="0 0 0" />
      <geometry>
        <mesh
          filename="../meshes/left_hip_link.STL" />
      </geometry>
    </collision>
  </link>
  <joint
    name="left_hip_joint"
    type="revolute">
    <origin
      xyz="0 0.0428 0.075997"
      rpy="0 0 0" />
    <parent
      link="base_link" />
    <child
      link="left_hip_link" />
    <axis
      xyz="0 1 0" />
    <dynamics damping="1.0" friction="0.0" />
    <limit
      lower="-1.57"
      upper="1.57"
      effort="80"
      velocity="15" />
  </joint>
  <link
    name="left_knee_link">
    <inertial>
      <origin
        xyz="0.058585 -0.0059746 -0.081982"
        rpy="0 0 0" />
      <mass
        value="0.42" />
      <inertia
        ixx="0.0041242120"
        ixy="-0.00023141797"
        ixz="-0.0031190064"
        iyy="0.0068629562"
        iyz="0.00028573503"
        izz="0.0028355928" />
    </inertial>
    <visual>
      <origin
        xyz="0 0 0"
        rpy="0 0 0" />
      <geometry>
        <mesh
          filename="../meshes/left_knee_link.STL" />
      </geometry>
      <material
        name="">
        <color
          rgba="1 1 1 1" />
      </material>
    </visual>
    <collision>
      <origin
        xyz="0 0 0"
        rpy="0 0 0" />
      <geometry>
        <mesh
          filename="../meshes/left_knee_link.STL" />
      </geometry>
    </collision>
  </link>
  <joint
    name="left_knee_joint"
    type="revolute">
    <origin
      xyz="-0.12022 0.11148 -0.15983"
      rpy="0 0 0" />
    <parent
      link="left_hip_link" />
    <child
      link="left_knee_link" />
    <axis
      xyz="0 1 0" />
    <dynamics damping="1.0" friction="0.0" />
    <limit
      lower="-1.19"
      upper="0"
      effort="80"
      velocity="15" />
  </joint>
  <link
    name="left_wheel_link">
    <inertial>
      <origin
        xyz="-2.0554E-06 0.028353 3.331E-07"
        rpy="0 0 0" />
      <mass
        value="2.785" />
      <inertia
        ixx="0.037393423"
        ixy="3.1796E-07"
        ixz="0"
        iyy="0.073815378"
        iyz="0"
        izz="0.037393397" />
    </inertial>
    <visual>
      <origin
        xyz="0 0 0"
        rpy="0 0 0" />
      <geometry>
        <mesh
          filename="../meshes/left_wheel_link.STL" />
      </geometry>
      <material name="orange">
          <color rgba="1.0 0.4235294117647059 0.0392156862745098 1.0"/>
      </material>
    </visual>
    <collision>
      <origin
        xyz="0 0.02 0"
        rpy="1.5707963 0 0" />
      <geometry>
        <cylinder radius="0.16" length="0.035"/>
      </geometry>
    </collision>
  </link>
  <joint
    name="left_wheel_joint"
    type="revolute">
    <origin
      xyz="0.13397 0.01346 -0.1485"
      rpy="0 0 0" />
    <parent
      link="left_knee_link" />
    <child
      link="left_wheel_link" />
    <axis
      xyz="0 1 0" />
    <limit
      lower="-1000000" 
      upper="1000000"      
      effort="20"
      velocity="30" />
    <dynamics friction="0.01" />
  </joint>
  <link
    name="right_hip_link">
    <inertial>
      <origin
        xyz="-0.028034 -0.083955 -0.032251"
        rpy="0 0 0" />
      <mass
        value="5.1" />
      <inertia
        ixx="0.052637715"
        ixy="0.0038396366"
        ixz="0.0029020553"
        iyy="0.018328965"
        iyz="0.0038831563"
        izz="0.051893499" />
    </inertial>
    <visual>
      <origin
        xyz="0 0 0"
        rpy="0 0 0" />
      <geometry>
        <mesh
          filename="../meshes/right_hip_link.STL" />
      </geometry>
      <material
        name="">
        <color
          rgba="1 1 1 1" />
      </material>
    </visual>
    <collision>
      <origin
        xyz="0 0 0"
        rpy="0 0 0" />
      <geometry>
        <mesh
          filename="../meshes/right_hip_link.STL" />
      </geometry>
    </collision>
  </link>
  <joint
    name="right_hip_joint"
    type="revolute">
    <origin
      xyz="0 -0.0528 0.075997"
      rpy="0 0 0" />
    <parent
      link="base_link" />
    <child
      link="right_hip_link" />
    <axis
      xyz="0 1 0" />
    <dynamics damping="1.0" friction="0.0" />
    <limit
      lower="-1.57"
      upper="1.57"
      effort="80"
      velocity="15" />
  </joint>
  <link
    name="right_knee_link">
    <inertial>
      <origin
        xyz="0.060903 -0.0019333 -0.083431"
        rpy="0 0 0" />
      <mass
        value="0.42" />
      <inertia
        ixx="0.0041242120"
        ixy="-0.00023141797"
        ixz="-0.0031190064"
        iyy="0.0068629562"
        iyz="0.00028573503"
        izz="0.0028355928" />
    </inertial>
    <visual>
      <origin
        xyz="0 0 0"
        rpy="0 0 0" />
      <geometry>
        <mesh
          filename="../meshes/right_knee_link.STL" />
      </geometry>
      <material
        name="">
        <color
          rgba="1 1 1 1" />
      </material>
    </visual>
    <collision>
      <origin
        xyz="0 0 0"
        rpy="0 0 0" />
      <geometry>
        <mesh
          filename="../meshes/right_knee_link.STL" />
      </geometry>
    </collision>
  </link>
  <joint
    name="right_knee_joint"
    type="revolute">
    <origin
      xyz="-0.12022 -0.10364 -0.15983"
      rpy="0 0 0" />
    <parent
      link="right_hip_link" />
    <child
      link="right_knee_link" />
    <axis
      xyz="0 1 0" />
    <dynamics damping="1.0" friction="0.0" />
    <limit
      lower="-1.19"
      upper="0"
      effort="80"
      velocity="15" />
  </joint>
  <link
    name="right_wheel_link">
    <inertial>
      <origin
        xyz="-2.0311E-06 -0.019153 -4.553E-07"
        rpy="0 0 0" />
      <mass
        value="2.785" />
      <inertia
        ixx="0.037393423"
        ixy="3.1796E-07"
        ixz="0"
        iyy="0.073815378"
        iyz="0"
        izz="0.037393397" />
    </inertial>
    <visual>
      <origin
        xyz="0 0 0"
        rpy="0 0 0" />
      <geometry>
        <mesh
          filename="../meshes/right_wheel_link.STL" />
      </geometry>
      <material name="orange">
          <color rgba="1.0 0.4235294117647059 0.0392156862745098 1.0"/>
      </material>
    </visual>
    <collision>
      <origin
        xyz="0 -0.02 0"
        rpy="1.5707963 0 0" />
      <geometry>
        <cylinder radius="0.16" length="0.035"/>
      </geometry>
    </collision>
  </link>
  <joint
    name="right_wheel_joint"
    type="revolute">
    <origin
      xyz="0.13397 -0.03046 -0.1485"
      rpy="0 0 0" />
    <parent
      link="right_knee_link" />
    <child
      link="right_wheel_link" />
    <axis
      xyz="0 1 0" />
    <limit
      lower="-1000000" 
      upper="1000000"      
      effort="20"
      velocity="30" />
    <dynamics friction="0.01" />
  </joint>
</robot>